Workbook

Sheet Sheet1
A1: ACTIVIDAD | E1: FECHA INICIO | F1: FECHA FIN | G1: FASE 1 | K1: FASE 2 | V1: FASE 3
G2: S1 | H2: S2 | I2: S3 | J2: S4 | K2: S5 | L2: S6 | M2: S7 | N2: S8 | O2: S9 | P2: S10 | Q2: S11 | R2: S12 | S2: S13 | T2: S14 | U2: S15 | V2: S16 | W2: S17 | X2: S18
A3: SPRINT 0 | E3: 46244 | F3: 46271
A4: Definición de proyecto Capstone
A5: Realización evidencia de Autoevaluación Competencias F1
A6: Realización evidencia de Diario de Reflexión F1
A7: Junta con cliente (N°1)
A8: Levantamiento de requisitos
A9: Realización evidencia de Autoevaluación F1
A10: Creación de Historias de Usuario
A11: Creación de PPT1
A12: Realización evidencia de Guía Estudiante F1
A13: Estructurado de Product Backlog
A14: Configuración de repositorio GIT
A15: Configuración del backend/API
... A19: Evaluación 1 (Hito 1)
A20: SPRINT 1 | E20: 46272 | F20: 46292
A21: Diseñar y crear modelo Relacional/No Relacional
A22: Registro de productos iniciales en base de datos (prueba)
A23: Implementación de servicios backend
A24: Implementación de vistas para usuario en tiempo real
A25: Junta con cliente (N°2)
A26: SPRINT 2 | E26: 46293 | F26: 46320
A27: Desarrollar aplicación móvil
A28: Evaluación 2 (Hito 2)
A29: Configurar envío de notificaciones "push" ante ofertas o cambios de precio
A30: Construir script automatizado para webscraping
A31: Creación función de escaneo de codigo de barras
A32: Junta con cliente (N°3)
A33: SPRINT 3 | E33: 46321 | F33: 46341
A34: Configurar notificaciones de falta stock en la pagina del proveedor
A35: Desarrollar agente de IA de reconocimiento de voz
A36: Implementar agente de IA de reconocimiento de voz para resolver consultas
A37: Ejecución de pruebas unitarias entre plataformas
A38: Ejecución de pruebas de carga
A39: Junta con cliente (N°4)
A40: SPRINT 4 | E40: 46342 | F40: 46362
A41: Redacción de informe final
A42: Creación de manual de usuario y guía de despliegue
A43: Preparación de la presentación y defensa
...

Sheet Tareas
A1: Tareas del proyecto Capstone
A2: Fecha de término (opcional): si una tarea está 'Hecho' y no tiene fecha, se asume que terminó el último día de su sprint.
A4: Sprint | B4: Actividad | C4: Puntos | D4: Estado | E4: Fecha de término | F4: Fecha considerada
A5: =Sheet1!$A$3 -> SPRINT 0 | B5: =Sheet1!$A$4 -> Definición de proyecto Capstone | C5: 1 | D5: Hecho | F5: =IF($D5="Hecho",IF($E5="",INDEX(Sheet1!$F$1:$F$44,MATCH($A5,Sheet1!$A$1:$A$44,0)),$E5),"") -> 46271
A6: =Sheet1!$A$3 -> SPRINT 0 | B6: =Sheet1!$A$5 -> Realización evidencia de Autoevaluación Competencias F1 | C6: 1 | D6: Hecho | F6: =IF($D6="Hecho",IF($E6="",INDEX(Sheet1!$F$1:$F$44,MATCH($A6,Sheet1!$A$1:$A$44,0)),$E6),"") -> 46271
A7: =Sheet1!$A$3 -> SPRINT 0 | B7: =Sheet1!$A$6 -> Realización evidencia de Diario de Reflexión F1 | C7: 1 | D7: Hecho | F7: =IF($D7="Hecho",IF($E7="",INDEX(Sheet1!$F$1:$F$44,MATCH($A7,Sheet1!$A$1:$A$44,0)),$E7),"") -> 46271
A8: =Sheet1!$A$3 -> SPRINT 0 | B8: =Sheet1!$A$7 -> Junta con cliente (N°1) | C8: 1 | D8: Hecho | F8: =IF($D8="Hecho",IF($E8="",INDEX(Sheet1!$F$1:$F$44,MATCH($A8,Sheet1!$A$1:$A$44,0)),$E8),"") -> 46271
A9: =Sheet1!$A$3 -> SPRINT 0 | B9: =Sheet1!$A$8 -> Levantamiento de requisitos | C9: 1 | D9: Hecho | F9: =IF($D9="Hecho",IF($E9="",INDEX(Sheet1!$F$1:$F$44,MATCH($A9,Sheet1!$A$1:$A$44,0)),$E9),"") -> 46271
A10: =Sheet1!$A$3 -> SPRINT 0 | B10: =Sheet1!$A$9 -> Realización evidencia de Autoevaluación F1 | C10: 1 | D10: Hecho | F10: =IF($D10="Hecho",IF($E10="",INDEX(Sheet1!$F$1:$F$44,MATCH($A10,Sheet1!$A$1:$A$44,0)),$E10),"") -> 46271
A11: =Sheet1!$A$3 -> SPRINT 0 | B11: =Sheet1!$A$10 -> Creación de Historias de Usuario | C11: 1 | D11: Hecho | F11: =IF($D11="Hecho",IF($E11="",INDEX(Sheet1!$F$1:$F$44,MATCH($A11,Sheet1!$A$1:$A$44,0)),$E11),"") -> 46271
A12: =Sheet1!$A$3 -> SPRINT 0 | B12: =Sheet1!$A$11 -> Creación de PPT1 | C12: 1 | D12: Hecho | F12: =IF($D12="Hecho",IF($E12="",INDEX(Sheet1!$F$1:$F$44,MATCH($A12,Sheet1!$A$1:$A$44,0)),$E12),"") -> 46271
A13: =Sheet1!$A$3 -> SPRINT 0 | B13: =Sheet1!$A$12 -> Realización evidencia de Guía Estudiante F1 | C13: 1 | D13: Hecho | F13: =IF($D13="Hecho",IF($E13="",INDEX(Sheet1!$F$1:$F$44,MATCH($A13,Sheet1!$A$1:$A$44,0)),$E13),"") -> 46271
A14: =Sheet1!$A$3 -> SPRINT 0 | B14: =Sheet1!$A$13 -> Estructurado de Product Backlog | C14: 1 | D14: Hecho | F14: =IF($D14="Hecho",IF($E14="",INDEX(Sheet1!$F$1:$F$44,MATCH($A14,Sheet1!$A$1:$A$44,0)),$E14),"") -> 46271
A15: =Sheet1!$A$3 -> SPRINT 0 | B15: =Sheet1!$A$14 -> Configuración de repositorio GIT | C15: 1 | D15: Hecho | F15: =IF($D15="Hecho",IF($E15="",INDEX(Sheet1!$F$1:$F$44,MATCH($A15,Sheet1!$A$1:$A$44,0)),$E15),"") -> 46271
A16: =Sheet1!$A$3 -> SPRINT 0 | B16: =Sheet1!$A$15 -> Configuración del backend/API | C16: 1 | D16: Hecho | F16: =IF($D16="Hecho",IF($E16="",INDEX(Sheet1!$F$1:$F$44,MATCH($A16,Sheet1!$A$1:$A$44,0)),$E16),"") -> 46271
A17: =Sheet1!$A$3 -> SPRINT 0 | B17: =Sheet1!$A$16 -> Configuración del VPS/Servidor | C17: 1 | D17: Hecho | F17: =IF($D17="Hecho",IF($E17="",INDEX(Sheet1!$F$1:$F$44,MATCH($A17,Sheet1!$A$1:$A$44,0)),$E17),"") -> 46271
A18: =Sheet1!$A$3 -> SPRINT 0 | B18: =Sheet1!$A$17 -> Implementación de políticas de seguridad y autenticación | C18: 1 | D18: Hecho | F18: =IF($D18="Hecho",IF($E18="",INDEX(Sheet1!$F$1:$F$44,MATCH($A18,Sheet1!$A$1:$A$44,0)),$E18),"") -> 46271
A19: =Sheet1!$A$3 -> SPRINT 0 | B19: =Sheet1!$A$18 -> Planilla Evaluación F1 | C19: 1 | D19: Hecho | F19: =IF($D19="Hecho",IF($E19="",INDEX(Sheet1!$F$1:$F$44,MATCH($A19,Sheet1!$A$1:$A$44,0)),$E19),"") -> 46271
A20: =Sheet1!$A$3 -> SPRINT 0 | B20: =Sheet1!$A$19 -> Evaluación 1 (Hito 1) | C20: 1 | D20: Hecho | F20: =IF($D20="Hecho",IF($E20="",INDEX(Sheet1!$F$1:$F$44,MATCH($A20,Sheet1!$A$1:$A$44,0)),$E20),"") -> 46271
A21: =Sheet1!$A$20 -> SPRINT 1 | B21: =Sheet1!$A$21 -> Diseñar y crear modelo Relacional/No Relacional | C21: 1 | D21: Hecho | F21: =IF($D21="Hecho",IF($E21="",INDEX(Sheet1!$F$1:$F$44,MATCH($A21,Sheet1!$A$1:$A$44,0)),$E21),"") -> 46292
A22: =Sheet1!$A$20 -> SPRINT 1 | B22: =Sheet1!$A$22 -> Registro de productos iniciales en base de datos (prueba) | C22: 1 | D22: Hecho | F22: =IF($D22="Hecho",IF($E22="",INDEX(Sheet1!$F$1:$F$44,MATCH($A22,Sheet1!$A$1:$A$44,0)),$E22),"") -> 46292
A23: =Sheet1!$A$20 -> SPRINT 1 | B23: =Sheet1!$A$23 -> Implementación de servicios backend | C23: 1 | D23: Hecho | F23: =IF($D23="Hecho",IF($E23="",INDEX(Sheet1!$F$1:$F$44,MATCH($A23,Sheet1!$A$1:$A$44,0)),$E23),"") -> 46292
A24: =Sheet1!$A$20 -> SPRINT 1 | B24: =Sheet1!$A$24 -> Implementación de vistas para usuario en tiempo real | C24: 1 | D24: Hecho | F24: =IF($D24="Hecho",IF($E24="",INDEX(Sheet1!$F$1:$F$44,MATCH($A24,Sheet1!$A$1:$A$44,0)),$E24),"") -> 46292
A25: =Sheet1!$A$20 -> SPRINT 1 | B25: =Sheet1!$A$25 -> Junta con cliente (N°2) | C25: 1 | D25: Hecho | F25: =IF($D25="Hecho",IF($E25="",INDEX(Sheet1!$F$1:$F$44,MATCH($A25,Sheet1!$A$1:$A$44,0)),$E25),"") -> 46292
A26: =Sheet1!$A$26 -> SPRINT 2 | B26: =Sheet1!$A$30 -> Construir script automatizado para webscraping | C26: 1 | D26: Pendiente | F26: =IF($D26="Hecho",IF($E26="",INDEX(Sheet1!$F$1:$F$44,MATCH($A26,Sheet1!$A$1:$A$44,0)),$E26),"")
A27: =Sheet1!$A$26 -> SPRINT 2 | B27: =Sheet1!$A$27 -> Desarrollar aplicación móvil | C27: 1 | D27: Pendiente | F27: =IF($D27="Hecho",IF($E27="",INDEX(Sheet1!$F$1:$F$44,MATCH($A27,Sheet1!$A$1:$A$44,0)),$E27),"")
A28: =Sheet1!$A$26 -> SPRINT 2 | B28: =Sheet1!$A$28 -> Evaluación 2 (Hito 2) | C28: 1 | D28: Pendiente | F28: =IF($D28="Hecho",IF($E28="",INDEX(Sheet1!$F$1:$F$44,MATCH($A28,Sheet1!$A$1:$A$44,0)),$E28),"")
A29: =Sheet1!$A$26 -> SPRINT 2 | B29: =Sheet1!$A$29 -> Configurar envío de notificaciones "push" ante ofertas o cambios de precio | C29: 1 | D29: Pendiente | F29: =IF($D29="Hecho",IF($E29="",INDEX(Sheet1!$F$1:$F$44,MATCH($A29,Sheet1!$A$1:$A$44,0)),$E29),"")
A30: =Sheet1!$A$26 -> SPRINT 2 | B30: =Sheet1!$A$31 -> Creación función de escaneo de codigo de barras | C30: 1 | D30: Pendiente | F30: =IF($D30="Hecho",IF($E30="",INDEX(Sheet1!$F$1:$F$44,MATCH($A30,Sheet1!$A$1:$A$44,0)),$E30),"")
A31: =Sheet1!$A$26 -> SPRINT 2 | B31: =Sheet1!$A$32 -> Junta con cliente (N°3) | C31: 1 | D31: Pendiente | F31: =IF($D31="Hecho",IF($E31="",INDEX(Sheet1!$F$1:$F$44,MATCH($A31,Sheet1!$A$1:$A$44,0)),$E31),"")
A32: =Sheet1!$A$33 -> SPRINT 3 | B32: =Sheet1!$A$34 -> Configurar notificaciones de falta stock en la pagina del proveedor | C32: 1 | D32: Pendiente | F32: =IF($D32="Hecho",IF($E32="",INDEX(Sheet1!$F$1:$F$44,MATCH($A32,Sheet1!$A$1:$A$44,0)),$E32),"")
A33: =Sheet1!$A$33 -> SPRINT 3 | B33: =Sheet1!$A$35 -> Desarrollar agente de IA de reconocimiento de voz | C33: 1 | D33: Pendiente | F33: =IF($D33="Hecho",IF($E33="",INDEX(Sheet1!$F$1:$F$44,MATCH($A33,Sheet1!$A$1:$A$44,0)),$E33),"")
A34: =Sheet1!$A$33 -> SPRINT 3 | B34: =Sheet1!$A$36 -> Implementar agente de IA de reconocimiento de voz para resolver consultas | C34: 1 | D34: Pendiente | F34: =IF($D34="Hecho",IF($E34="",INDEX(Sheet1!$F$1:$F$44,MATCH($A34,Sheet1!$A$1:$A$44,0)),$E34),"")
A35: =Sheet1!$A$33 -> SPRINT 3 | B35: =Sheet1!$A$37 -> Ejecución de pruebas unitarias entre plataformas | C35: 1 | D35: Pendiente | F35: =IF($D35="Hecho",IF($E35="",INDEX(Sheet1!$F$1:$F$44,MATCH($A35,Sheet1!$A$1:$A$44,0)),$E35),"")
A36: =Sheet1!$A$33 -> SPRINT 3 | B36: =Sheet1!$A$38 -> Ejecución de pruebas de carga | C36: 1 | D36: Pendiente | F36: =IF($D36="Hecho",IF($E36="",INDEX(Sheet1!$F$1:$F$44,MATCH($A36,Sheet1!$A$1:$A$44,0)),$E36),"")
A37: =Sheet1!$A$33 -> SPRINT 3 | B37: =Sheet1!$A$39 -> Junta con cliente (N°4) | C37: 1 | D37: Pendiente | F37: =IF($D37="Hecho",IF($E37="",INDEX(Sheet1!$F$1:$F$44,MATCH($A37,Sheet1!$A$1:$A$44,0)),$E37),"")
A38: =Sheet1!$A$40 -> SPRINT 4 | B38: =Sheet1!$A$41 -> Redacción de informe final | C38: 1 | D38: Pendiente | F38: =IF($D38="Hecho",IF($E38="",INDEX(Sheet1!$F$1:$F$44,MATCH($A38,Sheet1!$A$1:$A$44,0)),$E38),"")
A39: =Sheet1!$A$40 -> SPRINT 4 | B39: =Sheet1!$A$42 -> Creación de manual de usuario y guía de despliegue | C39: 1 | D39: Pendiente | F39: =IF($D39="Hecho",IF($E39="",INDEX(Sheet1!$F$1:$F$44,MATCH($A39,Sheet1!$A$1:$A$44,0)),$E39),"")
A40: =Sheet1!$A$40 -> SPRINT 4 | B40: =Sheet1!$A$43 -> Preparación de la presentación y defensa | C40: 1 | D40: Pendiente | F40: =IF($D40="Hecho",IF($E40="",INDEX(Sheet1!$F$1:$F$44,MATCH($A40,Sheet1!$A$1:$A$44,0)),$E40),"")
A41: =Sheet1!$A$40 -> SPRINT 4 | B41: =Sheet1!$A$44 -> Evaluación 3 (Hito 3) | C41: 1 | D41: Pendiente | F41: =IF($D41="Hecho",IF($E41="",INDEX(Sheet1!$F$1:$F$44,MATCH($A41,Sheet1!$A$1:$A$44,0)),$E41),"")

Sheet Burndown S0
A1: Burndown Chart – Sprint 0
A2: Unidad: puntos de esfuerzo (1 punto = 1 actividad por defecto; se edita en la hoja 'Tareas'). Real = puntos pendientes al cierre de cada semana.
A4: Punto de medición | B4: Fecha | C4: Puntos completados (acum.) | D4: Restante – Ideal | E4: Restante – Real | G4: Resumen
A5: Inicio | B5: =$H$6 -> 46244 | C5: 0 | D5: =$H$8 -> 16 | E5: =$H$8 -> 16 | G5: Sprint | H5: =Sheet1!$A$3 -> SPRINT 0
A6: Semana 1 | B6: =$H$6+7*1-1 -> 46250 | C6: =IF($B6>TODAY(),NA(),SUMIFS(Tareas!$C$5:$C$41,Tareas!$A$5:$A$41,$H$5,Tareas!$F$5:$F$41,"<="&$B6)) -> 0 | D6: =$H$8*MAX(0,1-($B6-$H$6+1)/($H$7-$H$6+1)) -> 12 | E6: 12 | G6: Fecha inicio | H6: =Sheet1!$E$3 -> 46244
A7: Semana 2 | B7: =$H$6+7*2-1 -> 46257 | C7: =IF($B7>TODAY(),NA(),SUMIFS(Tareas!$C$5:$C$41,Tareas!$A$5:$A$41,$H$5,Tareas!$F$5:$F$41,"<="&$B7)) -> 0 | D7: =$H$8*MAX(0,1-($B7-$H$6+1)/($H$7-$H$6+1)) -> 8 | E7: 8 | G7: Fecha fin | H7: =Sheet1!$F$3 -> 46271
A8: Semana 3 | B8: =$H$6+7*3-1 -> 46264 | C8: =IF($B8>TODAY(),NA(),SUMIFS(Tareas!$C$5:$C$41,Tareas!$A$5:$A$41,$H$5,Tareas!$F$5:$F$41,"<="&$B8)) -> 0 | D8: =$H$8*MAX(0,1-($B8-$H$6+1)/($H$7-$H$6+1)) -> 4 | E8: 4 | G8: Total de puntos | H8: =SUMIFS(Tareas!$C$5:$C$41,Tareas!$A$5:$A$41,$H$5) -> 16
A9: Semana 4 | B9: =$H$6+7*4-1 -> 46271 | C9: =IF($B9>TODAY(),NA(),SUMIFS(Tareas!$C$5:$C$41,Tareas!$A$5:$A$41,$H$5,Tareas!$F$5:$F$41,"<="&$B9)) -> 16 | D9: =$H$8*MAX(0,1-($B9-$H$6+1)/($H$7-$H$6+1)) -> 0 | E9: =IF(ISNA($C9),NA(),$H$8-$C9) -> 0 | G9: Completados | H9: =SUMIFS(Tareas!$C$5:$C$41,Tareas!$A$5:$A$41,$H$5,Tareas!$D$5:$D$41,"Hecho") -> 16
G10: Restantes | H10: =H8-H9 -> 0
A11: Notas: 'Ideal' baja linealmente hasta 0 al fin del sprint. Los puntos futuros quedan ocultos se rellenan solos a medida que pasa el tiempo. | G11: Avance | H11: =IF(H8=0,0,H9/H8) -> 1

Sheet Burndown S1
A1: Burndown Chart – Sprint 1
A2: Unidad: puntos de esfuerzo (1 punto = 1 actividad por defecto; se edita en la hoja 'Tareas'). Real = puntos pendientes al cierre de cada semana.
A4: Punto de medición | B4: Fecha | C4: Puntos completados (acum.) | D4: Restante – Ideal | E4: Restante – Real | G4: Resumen
A5: Inicio | B5: =$H$6 -> 46272 | C5: 0 | D5: =$H$8 -> 5 | E5: =$H$8 -> 5 | G5: Sprint | H5: =Sheet1!$A$20 -> SPRINT 1
A6: Semana 1 | B6: =$H$6+7*1-1 -> 46278 | C6: =IF($B6>TODAY(),NA(),SUMIFS(Tareas!$C$5:$C$41,Tareas!$A$5:$A$41,$H$5,Tareas!$F$5:$F$41,"<="&$B6)) -> 0 | D6: =$H$8*MAX(0,1-($B6-$H$6+1)/($H$7-$H$6+1)) -> 3.3333333 | E6: 3.3 | G6: Fecha inicio | H6: =Sheet1!$E$20 -> 46272
A7: Semana 2 | B7: =$H$6+7*2-1 -> 46285 | C7: =IF($B7>TODAY(),NA(),SUMIFS(Tareas!$C$5:$C$41,Tareas!$A$5:$A$41,$H$5,Tareas!$F$5:$F$41,"<="&$B7)) -> 0 | D7: =$H$8*MAX(0,1-($B7-$H$6+1)/($H$7-$H$6+1)) -> 1.6666667 | E7: 1.7 | G7: Fecha fin | H7: =Sheet1!$F$20 -> 46292
A8: Semana 3 | B8: =$H$6+7*3-1 -> 46292 | C8: =IF($B8>TODAY(),NA(),SUMIFS(Tareas!$C$5:$C$41,Tareas!$A$5:$A$41,$H$5,Tareas!$F$5:$F$41,"<="&$B8)) -> 5 | D8: =$H$8*MAX(0,1-($B8-$H$6+1)/($H$7-$H$6+1)) -> 0 | E8: 0 | G8: Total de puntos | H8: =SUMIFS(Tareas!$C$5:$C$41,Tareas!$A$5:$A$41,$H$5) -> 5
G9: Completados | H9: =SUMIFS(Tareas!$C$5:$C$41,Tareas!$A$5:$A$41,$H$5,Tareas!$D$5:$D$41,"Hecho") -> 5
A10: Notas: 'Ideal' baja linealmente hasta 0 al fin del sprint. Los puntos futuros quedan ocultos se rellenan solos a medida que pasa el tiempo. | G10: Restantes | H10: =H8-H9 -> 0
G11: Avance | H11: =IF(H8=0,0,H9/H8) -> 1

Sheet Burndown S2
A1: Burndown Chart – Sprint 2
A2: Unidad: puntos de esfuerzo (1 punto = 1 actividad por defecto; se edita en la hoja 'Tareas'). Real = puntos pendientes al cierre de cada semana.
A4: Punto de medición | B4: Fecha | C4: Puntos completados (acum.) | D4: Restante – Ideal | E4: Restante – Real | G4: Resumen
A5: Inicio | B5: =$H$6 -> 46293 | C5: 1 | D5: =$H$8 -> 6 | E5: =$H$8 -> 6 | G5: Sprint | H5: =Sheet1!$A$26 -> SPRINT 2
A6: Semana 1 | B6: =$H$6+7*1-1 -> 46299 | C6: 1 | D6: =$H$8*MAX(0,1-($B6-$H$6+1)/($H$7-$H$6+1)) -> 4.5 | E6: =IF(ISNA($C6),NA(),$H$8-$C6) -> 5 | G6: Fecha inicio | H6: =Sheet1!$E$26 -> 46293
A7: Semana 2 | B7: =$H$6+7*2-1 -> 46306 | C7: 1 | D7: =$H$8*MAX(0,1-($B7-$H$6+1)/($H$7-$H$6+1)) -> 3 | E7: =IF(ISNA($C7),NA(),$H$8-$C7) -> 5 | G7: Fecha fin | H7: =Sheet1!$F$26 -> 46320
A8: Semana 3 | B8: =$H$6+7*3-1 -> 46313 | C8: 1 | D8: =$H$8*MAX(0,1-($B8-$H$6+1)/($H$7-$H$6+1)) -> 1.5 | E8: =IF(ISNA($C8),NA(),$H$8-$C8) -> 5 | G8: Total de puntos | H8: =SUMIFS(Tareas!$C$5:$C$41,Tareas!$A$5:$A$41,$H$5) -> 6
A9: Semana 4 | B9: =$H$6+7*4-1 -> 46320 | C9: 1 | D9: =$H$8*MAX(0,1-($B9-$H$6+1)/($H$7-$H$6+1)) -> 0 | E9: =IF(ISNA($C9),NA(),$H$8-$C9) -> 5 | G9: Completados | H9: =SUMIFS(Tareas!$C$5:$C$41,Tareas!$A$5:$A$41,$H$5,Tareas!$D$5:$D$41,"Hecho") -> 0
G10: Restantes | H10: =H8-H9 -> 6
A11: Notas: 'Ideal' baja linealmente hasta 0 al fin del sprint. Los puntos futuros quedan ocultos se rellenan solos a medida que pasa el tiempo. | G11: Avance | H11: =IF(H8=0,0,H9/H8) -> 0

Sheet Burndown S3
A1: Burndown Chart – Sprint 3
A2: Unidad: puntos de esfuerzo (1 punto = 1 actividad por defecto; se edita en la hoja 'Tareas'). Real = puntos pendientes al cierre de cada semana.
A4: Punto de medición | B4: Fecha | C4: Puntos completados (acum.) | D4: Restante – Ideal | E4: Restante – Real | G4: Resumen
A5: Inicio | B5: =$H$6 -> 46321 | C5: 0 | D5: =$H$8 -> 6 | E5: =$H$8 -> 6 | G5: Sprint | H5: =Sheet1!$A$33 -> SPRINT 3
A6: Semana 1 | B6: =$H$6+7*1-1 -> 46327 | C6: =IF($B6>TODAY(),NA(),SUMIFS(Tareas!$C$5:$C$41,Tareas!$A$5:$A$41,$H$5,Tareas!$F$5:$F$41,"<="&$B6)) -> #N/A | D6: =$H$8*MAX(0,1-($B6-$H$6+1)/($H$7-$H$6+1)) -> 4 | E6: =IF(ISNA($C6),NA(),$H$8-$C6) -> #N/A | G6: Fecha inicio | H6: =Sheet1!$E$33 -> 46321
A7: Semana 2 | B7: =$H$6+7*2-1 -> 46334 | C7: =IF($B7>TODAY(),NA(),SUMIFS(Tareas!$C$5:$C$41,Tareas!$A$5:$A$41,$H$5,Tareas!$F$5:$F$41,"<="&$B7)) -> #N/A | D7: =$H$8*MAX(0,1-($B7-$H$6+1)/($H$7-$H$6+1)) -> 2 | E7: =IF(ISNA($C7),NA(),$H$8-$C7) -> #N/A | G7: Fecha fin | H7: =Sheet1!$F$33 -> 46341
A8: Semana 3 | B8: =$H$6+7*3-1 -> 46341 | C8: =IF($B8>TODAY(),NA(),SUMIFS(Tareas!$C$5:$C$41,Tareas!$A$5:$A$41,$H$5,Tareas!$F$5:$F$41,"<="&$B8)) -> #N/A | D8: =$H$8*MAX(0,1-($B8-$H$6+1)/($H$7-$H$6+1)) -> 0 | E8: =IF(ISNA($C8),NA(),$H$8-$C8) -> #N/A | G8: Total de puntos | H8: =SUMIFS(Tareas!$C$5:$C$41,Tareas!$A$5:$A$41,$H$5) -> 6
G9: Completados | H9: =SUMIFS(Tareas!$C$5:$C$41,Tareas!$A$5:$A$41,$H$5,Tareas!$D$5:$D$41,"Hecho") -> 0
A10: Notas: 'Ideal' baja linealmente hasta 0 al fin del sprint. Los puntos futuros quedan ocultos se rellenan solos a medida que pasa el tiempo. | G10: Restantes | H10: =H8-H9 -> 6
G11: Avance | H11: =IF(H8=0,0,H9/H8) -> 0

Sheet Burndown S4
A1: Burndown Chart – Sprint 4
A2: Unidad: puntos de esfuerzo (1 punto = 1 actividad por defecto; se edita en la hoja 'Tareas'). Real = puntos pendientes al cierre de cada semana.
A4: Punto de medición | B4: Fecha | C4: Puntos completados (acum.) | D4: Restante – Ideal | E4: Restante – Real | G4: Resumen
A5: Inicio | B5: =$H$6 -> 46342 | C5: 0 | D5: =$H$8 -> 4 | E5: =$H$8 -> 4 | G5: Sprint | H5: =Sheet1!$A$40 -> SPRINT 4
A6: Semana 1 | B6: =$H$6+7*1-1 -> 46348 | C6: =IF($B6>TODAY(),NA(),SUMIFS(Tareas!$C$5:$C$41,Tareas!$A$5:$A$41,$H$5,Tareas!$F$5:$F$41,"<="&$B6)) -> #N/A | D6: =$H$8*MAX(0,1-($B6-$H$6+1)/($H$7-$H$6+1)) -> 2.6666667 | E6: =IF(ISNA($C6),NA(),$H$8-$C6) -> #N/A | G6: Fecha inicio | H6: =Sheet1!$E$40 -> 46342
A7: Semana 2 | B7: =$H$6+7*2-1 -> 46355 | C7: =IF($B7>TODAY(),NA(),SUMIFS(Tareas!$C$5:$C$41,Tareas!$A$5:$A$41,$H$5,Tareas!$F$5:$F$41,"<="&$B7)) -> #N/A | D7: =$H$8*MAX(0,1-($B7-$H$6+1)/($H$7-$H$6+1)) -> 1.3333333 | E7: =IF(ISNA($C7),NA(),$H$8-$C7) -> #N/A | G7: Fecha fin | H7: =Sheet1!$F$40 -> 46362
A8: Semana 3 | B8: =$H$6+7*3-1 -> 46362 | C8: =IF($B8>TODAY(),NA(),SUMIFS(Tareas!$C$5:$C$41,Tareas!$A$5:$A$41,$H$5,Tareas!$F$5:$F$41,"<="&$B8)) -> #N/A | D8: =$H$8*MAX(0,1-($B8-$H$6+1)/($H$7-$H$6+1)) -> 0 | E8: =IF(ISNA($C8),NA(),$H$8-$C8) -> #N/A | G8: Total de puntos | H8: =SUMIFS(Tareas!$C$5:$C$41,Tareas!$A$5:$A$41,$H$5) -> 4
G9: Completados | H9: =SUMIFS(Tareas!$C$5:$C$41,Tareas!$A$5:$A$41,$H$5,Tareas!$D$5:$D$41,"Hecho") -> 0
A10: Notas: 'Ideal' baja linealmente hasta 0 al fin del sprint. Los puntos futuros quedan ocultos se rellenan solos a medida que pasa el tiempo. | G10: Restantes | H10: =H8-H9 -> 4
G11: Avance | H11: =IF(H8=0,0,H9/H8) -> 0
