Workbook

Sheet Sheet1
A1: ACTIVIDAD | E1: FECHA INICIO | F1: FECHA FIN | G1: FASE 1 | K1: FASE 2 | V1: FASE 3
G2: S1 | H2: S2 | I2: S3 | J2: S4 | K2: S5 | L2: S6 | M2: S7 | N2: S8 | O2: S9 | P2: S10 | Q2: S11 | R2: S12 | S2: S13 | T2: S14 | U2: S15 | V2: S16 | W2: S17 | X2: S18
A3: SPRINT 0 | E3: 46244 | F3: 46271
A4: Definición de proyecto Capstone
A5: Realización evidencia de Autoevaluación Competencias F1
A6: Realización evidencia de Diario de Reflexión F1
A7: Junta con cliente (N°1)
A8: Levantamiento de requisitos
A9: Realización evidencia de Autoevaluación F1
A10: Creación de Historias de Usuario
A11: Creación de PPT1
A12: Realización evidencia de Guía Estudiante F1
A13: Estructurado de Product Backlog
A14: Configuración de repositorio GIT
A15: Configuración del backend/API
... A19: Evaluación 1 (Hito 1)
A20: SPRINT 1 | E20: 46272 | F20: 46292
A21: Diseñar y crear modelo Relacional/No Relacional
A22: Registro de productos iniciales en base de datos (prueba)
A23: Implementación de servicios backend
A24: Implementación de vistas para usuario en tiempo real
A25: Junta con cliente (N°2)
A26: SPRINT 2 | E26: 46293 | F26: 46320
A27: Construir script automatizado para extracción de precios y actualización automatica en la base de datos
A28: Desarrollar aplicación móvil conectada a API
A29: Evaluación 2 (Hito 2)
A30: Configurar envío de notificaciones "push" ante ofertas o cambios de precio
A31: Creación función de escaneo de codigo de barras
A32: Junta con cliente (N°3)
A33: SPRINT 3 | E33: 46321 | F33: 46341
A34: Configurar notificaciones de falta stock en la pagina del proveedor
A35: Desarrollar agente de IA de reconocimiento de voz
A36: Implementar agente de IA de reconocimiento de voz para resolver consultas
A37: Ejecución de pruebas unitarias entre plataformas
A38: Ejecución de pruebas de carga
A39: Junta con cliente (N°4)
A40: SPRINT 4 | E40: 46342 | F40: 46362
A41: Redacción de informe final
A42: Creación de manual de usuario y guía de despliegue
A43: Preparación de la presentación y defensa
...

Sheet Tareas
A1: Tareas del proyecto Capstone
A4: Sprint | B4: Actividad | C4: Puntos | D4: Estado
A5: =Sheet1!$A$3 -> SPRINT 0 | B5: =Sheet1!$A$4 -> Definición de proyecto Capstone | C5: 1 | D5: Hecho
A6: =Sheet1!$A$3 -> SPRINT 0 | B6: =Sheet1!$A$5 -> Realización evidencia de Autoevaluación Competencias F1 | C6: 1 | D6: Hecho
A7: =Sheet1!$A$3 -> SPRINT 0 | B7: =Sheet1!$A$6 -> Realización evidencia de Diario de Reflexión F1 | C7: 1 | D7: Hecho
A8: =Sheet1!$A$3 -> SPRINT 0 | B8: =Sheet1!$A$7 -> Junta con cliente (N°1) | C8: 1 | D8: Hecho
A9: =Sheet1!$A$3 -> SPRINT 0 | B9: =Sheet1!$A$8 -> Levantamiento de requisitos | C9: 1 | D9: Hecho
A10: =Sheet1!$A$3 -> SPRINT 0 | B10: =Sheet1!$A$9 -> Realización evidencia de Autoevaluación F1 | C10: 1 | D10: Hecho
A11: =Sheet1!$A$3 -> SPRINT 0 | B11: =Sheet1!$A$10 -> Creación de Historias de Usuario | C11: 1 | D11: Hecho
A12: =Sheet1!$A$3 -> SPRINT 0 | B12: =Sheet1!$A$11 -> Creación de PPT1 | C12: 1 | D12: Hecho
A13: =Sheet1!$A$3 -> SPRINT 0 | B13: =Sheet1!$A$12 -> Realización evidencia de Guía Estudiante F1 | C13: 1 | D13: Hecho
A14: =Sheet1!$A$3 -> SPRINT 0 | B14: =Sheet1!$A$13 -> Estructurado de Product Backlog | C14: 1 | D14: Hecho
A15: =Sheet1!$A$3 -> SPRINT 0 | B15: =Sheet1!$A$14 -> Configuración de repositorio GIT | C15: 1 | D15: Hecho
A16: =Sheet1!$A$3 -> SPRINT 0 | B16: =Sheet1!$A$15 -> Configuración del backend/API | C16: 1 | D16: Hecho
A17: =Sheet1!$A$3 -> SPRINT 0 | B17: =Sheet1!$A$16 -> Configuración del VPS/Servidor | C17: 1 | D17: Hecho
A18: =Sheet1!$A$3 -> SPRINT 0 | B18: =Sheet1!$A$17 -> Implementación de políticas de seguridad y autenticación | C18: 1 | D18: Hecho
A19: =Sheet1!$A$3 -> SPRINT 0 | B19: =Sheet1!$A$18 -> Planilla Evaluación F1 | C19: 1 | D19: Hecho
A20: =Sheet1!$A$3 -> SPRINT 0 | B20: =Sheet1!$A$19 -> Evaluación 1 (Hito 1) | C20: 1 | D20: Hecho
A21: =Sheet1!$A$20 -> SPRINT 1 | B21: =Sheet1!$A$21 -> Diseñar y crear modelo Relacional/No Relacional | C21: 1 | D21: Hecho
A22: =Sheet1!$A$20 -> SPRINT 1 | B22: =Sheet1!$A$22 -> Registro de productos iniciales en base de datos (prueba) | C22: 1 | D22: Hecho
A23: =Sheet1!$A$20 -> SPRINT 1 | B23: =Sheet1!$A$23 -> Implementación de servicios backend | C23: 1 | D23: Pendiente
A24: =Sheet1!$A$20 -> SPRINT 1 | B24: =Sheet1!$A$24 -> Implementación de vistas para usuario en tiempo real | C24: 1 | D24: Pendiente
A25: =Sheet1!$A$20 -> SPRINT 1 | B25: =Sheet1!$A$25 -> Junta con cliente (N°2) | C25: 1 | D25: Hecho
A26: =Sheet1!$A$26 -> SPRINT 2 | B26: =Sheet1!$A$27 -> Construir script automatizado para extracción de precios y actualización automatica en la base de datos | C26: 1 | D26: Pendiente
A27: =Sheet1!$A$26 -> SPRINT 2 | B27: =Sheet1!$A$28 -> Desarrollar aplicación móvil conectada a API | C27: 1 | D27: Pendiente
A28: =Sheet1!$A$26 -> SPRINT 2 | B28: =Sheet1!$A$29 -> Evaluación 2 (Hito 2) | C28: 1 | D28: Pendiente
A29: =Sheet1!$A$26 -> SPRINT 2 | B29: =Sheet1!$A$30 -> Configurar envío de notificaciones "push" ante ofertas o cambios de precio | C29: 1 | D29: Pendiente
A30: =Sheet1!$A$26 -> SPRINT 2 | B30: =Sheet1!$A$31 -> Creación función de escaneo de codigo de barras | C30: 1 | D30: Pendiente
A31: =Sheet1!$A$26 -> SPRINT 2 | B31: =Sheet1!$A$32 -> Junta con cliente (N°3) | C31: 1 | D31: Pendiente
A32: =Sheet1!$A$33 -> SPRINT 3 | B32: =Sheet1!$A$34 -> Configurar notificaciones de falta stock en la pagina del proveedor | C32: 1 | D32: Pendiente
A33: =Sheet1!$A$33 -> SPRINT 3 | B33: =Sheet1!$A$35 -> Desarrollar agente de IA de reconocimiento de voz | C33: 1 | D33: Pendiente
A34: =Sheet1!$A$33 -> SPRINT 3 | B34: =Sheet1!$A$36 -> Implementar agente de IA de reconocimiento de voz para resolver consultas | C34: 1 | D34: Pendiente
A35: =Sheet1!$A$33 -> SPRINT 3 | B35: =Sheet1!$A$37 -> Ejecución de pruebas unitarias entre plataformas | C35: 1 | D35: Pendiente
A36: =Sheet1!$A$33 -> SPRINT 3 | B36: =Sheet1!$A$38 -> Ejecución de pruebas de carga | C36: 1 | D36: Pendiente
A37: =Sheet1!$A$33 -> SPRINT 3 | B37: =Sheet1!$A$39 -> Junta con cliente (N°4) | C37: 1 | D37: Pendiente
A38: =Sheet1!$A$40 -> SPRINT 4 | B38: =Sheet1!$A$41 -> Redacción de informe final | C38: 1 | D38: Pendiente
A39: =Sheet1!$A$40 -> SPRINT 4 | B39: =Sheet1!$A$42 -> Creación de manual de usuario y guía de despliegue | C39: 1 | D39: Pendiente
A40: =Sheet1!$A$40 -> SPRINT 4 | B40: =Sheet1!$A$43 -> Preparación de la presentación y defensa | C40: 1 | D40: Pendiente
A41: =Sheet1!$A$40 -> SPRINT 4 | B41: =Sheet1!$A$44 -> Evaluación 3 (Hito 3) | C41: 1 | D41: Pendiente

Sheet Burndown
A1: Burndown Chart – Proyecto Capstone
A2: Unidad: puntos de esfuerzo (por defecto 1 punto = 1 actividad). Se edita en la hoja 'Tareas'.
A4: Punto de medición | B4: Fecha | C4: Puntos planificados | D4: Puntos completados | E4: Restante – Plan (Gantt) | F4: Restante – Real | H4: Resumen
A5: Inicio | B5: =Sheet1!$E$3 -> 46244 | E5: =SUM(Tareas!$C$5:$C$41) -> 37 | F5: =E5 -> 37 | H5: Total de puntos | I5: =E5 -> 37
A6: Sprint 0 | B6: =Sheet1!$F$3 -> 46271 | C6: =SUMIFS(Tareas!$C$5:$C$41,Tareas!$A$5:$A$41,$A6) -> 16 | D6: =SUMIFS(Tareas!$C$5:$C$41,Tareas!$A$5:$A$41,$A6,Tareas!$D$5:$D$41,"Hecho") -> 16 | E6: =E5-C6 -> 21 | F6: =$E$5-SUM($D$6:D6) -> 21 | H6: Completados | I6: =SUM(D6:D10) -> 19
A7: Sprint 1 | B7: =Sheet1!$F$20 -> 46292 | C7: =SUMIFS(Tareas!$C$5:$C$41,Tareas!$A$5:$A$41,$A7) -> 5 | D7: =SUMIFS(Tareas!$C$5:$C$41,Tareas!$A$5:$A$41,$A7,Tareas!$D$5:$D$41,"Hecho") -> 3 | E7: =E6-C7 -> 16 | F7: =$E$5-SUM($D$6:D7) -> 18 | H7: Restantes | I7: =I5-I6 -> 18
A8: Sprint 2 | B8: =Sheet1!$F$26 -> 46320 | C8: =SUMIFS(Tareas!$C$5:$C$41,Tareas!$A$5:$A$41,$A8) -> 6 | D8: =SUMIFS(Tareas!$C$5:$C$41,Tareas!$A$5:$A$41,$A8,Tareas!$D$5:$D$41,"Hecho") -> 0 | E8: =E7-C8 -> 10 | H8: Avance | I8: =IF(I5=0,0,I6/I5) -> 0.51351351
A9: Sprint 3 | B9: =Sheet1!$F$33 -> 46341 | C9: =SUMIFS(Tareas!$C$5:$C$41,Tareas!$A$5:$A$41,$A9) -> 6 | D9: =SUMIFS(Tareas!$C$5:$C$41,Tareas!$A$5:$A$41,$A9,Tareas!$D$5:$D$41,"Hecho") -> 0 | E9: =E8-C9 -> 4
A10: Sprint 4 | B10: =Sheet1!$F$40 -> 46362 | C10: =SUMIFS(Tareas!$C$5:$C$41,Tareas!$A$5:$A$41,$A10) -> 4 | D10: =SUMIFS(Tareas!$C$5:$C$41,Tareas!$A$5:$A$41,$A10,Tareas!$D$5:$D$41,"Hecho") -> 0 | E10: =E9-C10 -> 0
